<gazebo>
  <plugin name="gazebo_ros_control" filename="libgazebo_ros_control.so">
    <robotNamespace>/MotorSim</robotNamespace>
  </plugin>
</gazebo>
<robot
  name="StepMotor">
  <link
    name="base_link">
    <inertial>
      <origin
        xyz="-0.000859097170120963 -0.00022159587417355 0.000341800187754871"
        rpy="0 0 0" />
      <mass
        value="0.302970386242336" />
      <inertia
        ixx="4.49769854527357E-05"
        ixy="-1.98854219257748E-21"
        ixz="-3.30872245021211E-24"
        iyy="1.70602116721423E-07"
        iyz="3.93076227085199E-21"
        izz="4.49769854527357E-05" />
    </inertial>
    <visual>
      <origin
        xyz="0 0 0"
        rpy="0 0 0" />
      <geometry>
        <mesh
          filename="package://StepMotor/meshes/base_link.STL" />
      </geometry>
      <material
        name="">
        <color
          rgba="0.898039215686275 0.917647058823529 0.929411764705882 1" />
      </material>
    </visual>
    <collision>
      <origin
        xyz="0 0 0"
        rpy="0 0 0" />
      <geometry>
        <mesh
          filename="package://StepMotor/meshes/base_link.STL" />
      </geometry>
    </collision>
  </link>
  <link
    name="Shaft">
    <inertial>
      <origin
        xyz="-0.00012249817140968 0.0141141740469127 2.16712378782197E-10"
        rpy="0 0 0" />
      <mass
        value="0.00509177024649685" />
      <inertia
        ixx="0"
        ixy="0"
        ixz="0"
        iyy="0"
        iyz="0"
        izz="0" />
    </inertial>
    <visual>
      <origin
        xyz="0 0 0"
        rpy="0 0 0" />
      <geometry>
        <mesh
          filename="package://StepMotor/meshes/Shaft.STL" />
      </geometry>
      <material
        name="">
        <color
          rgba="0.666666666666667 0.698039215686274 0.768627450980392 1" />
      </material>
    </visual>
    <collision>
      <origin
        xyz="0 0 0"
        rpy="0 0 0" />
      <geometry>
        <mesh
          filename="package://StepMotor/meshes/Shaft.STL" />
      </geometry>
    </collision>
  </link>
  <joint
    name="Motor1"
    type="continuous">
    <origin
      xyz="-0.0008591 -0.0003418 0"
      rpy="1.5708 0 0" />
    <parent
      link="base_link" />
    <child
      link="Shaft" />
    <axis
      xyz="0 1 0" />
  </joint>
</robot>
