<?xml version='1.0'?>
<robot name="motorsim" xmlns:xacro="http://www.ros.org/wiki/xacro">
  <!-- Import all Gazebo-customization elements, including Gazebo colors -->
  <xacro:include filename="$(find motorsim_description)/urdf/stepmotor.gazebo" />
  <gazebo>
    <plugin name="gazebo_ros_control" filename="libgazebo_ros_control.so">
    </plugin>
  </gazebo>
  
  <!-- Used for fixing robot to Gazebo 'base_link'-->
  <link name="world"/>
  <joint name="fixed" type="fixed">
    <parent link="world"/>
    <child link="motorbase"/>
  </joint>
  
  <link name="motorbase">
    <inertial>
      <origin
        xyz="-1.73472347597681E-18 -0.000240520210148032 0.01935323513063"
        rpy="0 0 0" />
      <mass
        value="0.521692297282674" />
      <inertia
        ixx="0.000143281413851519"
        ixy="5.0594989079774E-23"
        ixz="-2.17038531015825E-14"
        iyy="0.000140541816548591"
        iyz="-1.73801685528978E-06"
        izz="0.000150985116656737" />
    </inertial>
    <visual>
      <origin
        xyz="0 0 0"
        rpy="0 0 0" />
      <geometry>
        <mesh
          filename="$(find motorsim_description)/meshes/motorbase.STL" />
      </geometry>
      <material
        name="">
        <color
          rgba="0.529411764705882 0.549019607843137 0.549019607843137 1" />
      </material>
    </visual>
    <collision>
      <origin
        xyz="0 0 0"
        rpy="0 0 0" />
      <geometry>
        <mesh
          filename="$(find motorsim_description)/meshes/motorbase.STL" />
      </geometry>
    </collision>
  </link>
  <link
    name="shaft">
    <inertial>
      <origin
        xyz="-5.57804855252433E-05 3.6442827916934E-05 -0.0323552342224554"
        rpy="0 0 0" />
      <mass
        value="0.00938942234002253" />
      <inertia
        ixx="3.02377687875403E-06"
        ixy="-4.4877695035017E-10"
        ixz="1.29981262495522E-08"
        iyy="3.0233831648333E-06"
        iyz="-8.49201066815104E-09"
        izz="2.88185683542568E-08" />
    </inertial>
    <visual>
      <origin
        xyz="0 0 0"
        rpy="0 0 0" />
      <geometry>
        <mesh
          filename="$(find motorsim_description)/meshes/shaft.STL" />
      </geometry>
      <material
        name="">
        <color
          rgba="0.776470588235294 0.756862745098039 0.737254901960784 1" />
      </material>
    </visual>
    <collision>
      <origin
        xyz="0 0 0"
        rpy="0 0 0" />
      <geometry>
        <mesh
          filename="$(find motorsim_description)/meshes/shaft.STL" />
      </geometry>
    </collision>
  </link>
  <joint
    name="joint1"
    type="continuous">
    <origin
      xyz="0 0 0.064"
      rpy="0 0 0" />
    <parent
      link="motorbase" />
    <child
      link="shaft" />
    <axis
      xyz="0 0 -1" />
  </joint>


  <transmission name="tran1">
    <type>transmission_interface/SimpleTransmission</type>
    <joint name="joint1">
      <hardwareInterface>hardware_interface/VelocityJointInterface</hardwareInterface>
    </joint>
    <actuator name="motor1">
      <hardwareInterface>hardware_interface/VelocityJointInterface</hardwareInterface>
      <mechanicalReduction>1</mechanicalReduction>
    </actuator>
  </transmission>

</robot>
