<?xml version='1.0'?>
<robot
  name="motorsim" xmlns:xacro="http://www.ros.org/wiki/xacro">
  <xacro:include filename="$(find motorsim_description)/urdf/stepmotor.gazebo" />
  <gazebo>
    <plugin name="gazebo_ros_control" filename="libgazebo_ros_control.so">
    </plugin>
  </gazebo>
  <link
    name="motorbase">
    <inertial>
      <origin
        xyz="-0.000859097170120963 -0.000341800187754871 -0.000199540178000858"
        rpy="0 0 0" />
      <mass
        value="1" />
      <inertia
        ixx="1"
        ixy="0"
        ixz="0"
        iyy="0"
        iyz="-1"
        izz="1" />
    </inertial>
    <visual>
      <origin
        xyz="0 0 0"
        rpy="0 0 0" />
      <geometry>
        <mesh
          filename="$(find motorsim_description)/meshes/motorbase.STL" />
      </geometry>
      <material
        name="">
        <color
          rgba="0.898039215686275 0.917647058823529 0.929411764705882 1" />
      </material>
    </visual>
    <collision>
      <origin
        xyz="0 0 0"
        rpy="0 0 0" />
      <geometry>
        <mesh
          filename="$(find motorsim_description)/meshes/motorbase.STL" />
      </geometry>
    </collision>
  </link>
  <link
    name="shaft">
    <inertial>
      <origin
        xyz="-0.000861121867187112 -0.000341800191336777 1.53512652504286E-05"
        rpy="0 0 0" />
      <mass
        value="0.5" />
      <inertia
        ixx="1"
        ixy="0"
        ixz="0"
        iyy="1"
        iyz="0"
        izz="1" />
    </inertial>
    <visual>
      <origin
        xyz="0 0 0"
        rpy="0 0 0" />
      <geometry>
        <mesh
          filename="$(find motorsim_description)/meshes/shaft.STL" />
      </geometry>
      <material
        name="">
        <color
          rgba="0.666666666666667 0.698039215686274 0.768627450980392 1" />
      </material>
    </visual>
    <collision>
      <origin
        xyz="0 0 0"
        rpy="0 0 0" />
      <geometry>
        <mesh
          filename="$(find motorsim_description)/meshes/shaft.STL" />
      </geometry>
    </collision>
  </link>
  <joint
    name="motorjoint"
    type="revolute">
    <origin
      xyz="0 0 0"
      rpy="0 0 0" />
    <parent
      link="motorbase" />
    <child
      link="shaft" />
    <axis
      xyz="0 0 1" />
<limit upper="3000" lower="-3000" effort="3000" velocity="1000"/>
  </joint>
</robot>
