<?xml version='1.0'?>
<robot
  name="motorsim" xmlns:xacro="http://www.ros.org/wiki/xacro">
  <xacro:include filename="$(find motorsim_description)/urdf/stepmotor.gazebo" />
  <gazebo>
    <plugin name="gazebo_ros_control" filename="libgazebo_ros_control.so">
    </plugin>
  </gazebo>
  <link
    name="motorbase">
    <inertial>
      <origin
        xyz="-0.000859097170120963 -0.000341800187754871 -0.000199540178000858"
        rpy="0 0 0" />
      <mass
        value="1" />
      <inertia
        ixx="1"
        ixy="0"
        ixz="0"
        iyy="1"
        iyz="0"
        izz="1" />
    </inertial>
    <visual>
      <origin
        xyz="0 0 0"
        rpy="0 0 0" />
      <geometry>
        <mesh
          filename="$(find motorsim_description)/meshes/motorbase.STL" />
      </geometry>
      <material
        name="">
        <color
          rgba="0.898039215686275 0.917647058823529 0.929411764705882 1" />
      </material>
    </visual>
    <collision>
      <origin
        xyz="0 0 0"
        rpy="0 0 0" />
      <geometry>
        <mesh
          filename="$(find motorsim_description)/meshes/motorbase.STL" />
      </geometry>
    </collision>
  </link>
  <link
    name="shaft">
    <inertial>
      <origin
        xyz="-0.00012249817140968 0.0141141740469127 2.16712378782197E-10"
        rpy="0 0 0" />
      <mass
        value="0.005" />
      <inertia
        ixx="0.1"
        ixy="0"
        ixz="0"
        iyy="0.0001"
        iyz="0"
        izz="0.0001" />
    </inertial>
    <visual>
      <origin
        xyz="0 0 0"
        rpy="0 0 0" />
      <geometry>
        <mesh
          filename="$(find motorsim_description)/meshes/shaft.STL" />
      </geometry>
      <material
        name="">
        <color
          rgba="0.666666666666667 0.698039215686274 0.768627450980392 1" />
      </material>
    </visual>
    <collision>
      <origin
        xyz="0 0 0"
        rpy="0 0 0" />
      <geometry>
        <mesh
          filename="$(find motorsim_description)/meshes/shaft.STL" />
      </geometry>
    </collision>
  </link>
  <joint
    name="motorjoint"
    type="continuous">
    <origin
      xyz="-0.0008591 -0.0003418 0"
      rpy="1.5708 0 0" />
    <parent
      link="motorbase" />
    <child
      link="shaft" />
    <axis
      xyz="0 1 0" />
<limit upper="360" lower="-360" effort="100" velocity="100"/>
  </joint>
</robot>
